<?xml version="1.0" ?>
<robot name="trial">
  <joint name="trial__link_0_JOINT_5" type="revolute">
    <parent link="trial__link_0"/>
    <child link="trial__link_2_clone_0"/>
    <origin xyz="-0.48467  0.7899   0.01329" rpy="1.5707 0     0"/>
    <axis xyz="1 0 0"/>
    <limit lower="-1.79769e+308" upper="1.79769e+308" effort="-1.0" velocity="-1.0"/>
  </joint>
  <joint name="trial__link_0_JOINT_6" type="revolute">
    <parent link="trial__link_0"/>
    <child link="trial__link_2_clone"/>
    <origin xyz="0.62408 -0.77137 -0.00612" rpy="1.5707 0     0"/>
    <axis xyz="1 0 0"/>
    <limit lower="-1.79769e+308" upper="1.79769e+308" effort="-1.0" velocity="-1.0"/>
  </joint>
  <joint name="trial__link_0_JOINT_7" type="revolute">
    <parent link="trial__link_0"/>
    <child link="trial__link_2_clone_1"/>
    <origin xyz="0.24293  0.78875 -0.00612" rpy="1.5707 0     0"/>
    <axis xyz="1 0 0"/>
    <limit lower="-1.79769e+308" upper="1.79769e+308" effort="-1.0" velocity="-1.0"/>
  </joint>
  <joint name="trial__link_0_JOINT_8" type="revolute">
    <parent link="trial__link_0"/>
    <child link="trial__link_2"/>
    <origin xyz="-0.48704 -0.77541 -0.00612" rpy="1.5707 0     0"/>
    <axis xyz="1 0 0"/>
    <limit lower="-1.79769e+308" upper="1.79769e+308" effort="-1.0" velocity="-1.0"/>
  </joint>
  <link name="trial__link_0">
    <inertial>
      <mass value="0.205443"/>
      <origin xyz="0 0 0" rpy="0 0 0"/>
      <inertia ixx="0.0174354" ixy="0" ixz="0" iyy="0.0395861" iyz="0" izz="0.0563914"/>
    </inertial>
    <collision name="trial__collision">
      <origin xyz="0.07428 -0.03193 -0.02644" rpy="0 0 0"/>
      <geometry>
        <box size="1.51454 1 0.13566"/>
      </geometry>
    </collision>
    <visual name="trial__visual">
      <origin xyz="0.07428 -0.03193 -0.02644" rpy="0 0 0"/>
      <geometry>
        <box size="1.51454 1 0.13566"/>
      </geometry>
    </visual>
  </link>
  <link name="trial__link_2">
    <inertial>
      <mass value="0.0174037"/>
      <origin xyz="0 0 0" rpy="1.707 0    0"/>
      <inertia ixx="0.000233463" ixy="0" ixz="0" iyy="0.000233463" iyz="0" izz="0.000446063"/>
    </inertial>
    <collision name="trial__collision">
      <origin xyz="0 0 0" rpy="0 0 0"/>
      <geometry>
        <cylinder radius="0.226408" length="0.084808"/>
      </geometry>
    </collision>
    <visual name="trial__visual">
      <origin xyz="0 0 0" rpy="0 0 0"/>
      <geometry>
        <cylinder radius="0.226408" length="0.0848081"/>
      </geometry>
    </visual>
  </link>
  <link name="trial__link_2_clone">
    <inertial>
      <mass value="0.0174037"/>
      <origin xyz="0 0 0" rpy="1.707 0    0"/>
      <inertia ixx="0.000233463" ixy="0" ixz="0" iyy="0.000233463" iyz="0" izz="0.000446063"/>
    </inertial>
    <collision name="trial__collision">
      <origin xyz="0 0 0" rpy="0 0 0"/>
      <geometry>
        <cylinder radius="0.226408" length="0.084808"/>
      </geometry>
    </collision>
    <visual name="trial__visual">
      <origin xyz="0 0 0" rpy="0 0 0"/>
      <geometry>
        <cylinder radius="0.226408" length="0.0848081"/>
      </geometry>
    </visual>
  </link>
  <link name="trial__link_2_clone_0">
    <inertial>
      <mass value="0.0174037"/>
      <origin xyz="0 0 0" rpy="1.707 0    0"/>
      <inertia ixx="0.000233463" ixy="0" ixz="0" iyy="0.000233463" iyz="0" izz="0.000446063"/>
    </inertial>
    <collision name="trial__collision">
      <origin xyz="0 0 0" rpy="0 0 0"/>
      <geometry>
        <cylinder radius="0.226408" length="0.084808"/>
      </geometry>
    </collision>
    <visual name="trial__visual">
      <origin xyz="0 0 0" rpy="0 0 0"/>
      <geometry>
        <cylinder radius="0.226408" length="0.0848081"/>
      </geometry>
    </visual>
  </link>
  <link name="trial__link_2_clone_1">
    <inertial>
      <mass value="0.0174037"/>
      <origin xyz="0 0 0" rpy="1.707 0    0"/>
      <inertia ixx="0.000233463" ixy="0" ixz="0" iyy="0.000233463" iyz="0" izz="0.000446063"/>
    </inertial>
    <collision name="trial__collision">
      <origin xyz="0 0 0" rpy="0 0 0"/>
      <geometry>
        <cylinder radius="0.226408" length="0.084808"/>
      </geometry>
    </collision>
    <visual name="trial__visual">
      <origin xyz="0 0 0" rpy="0 0 0"/>
      <geometry>
        <cylinder radius="0.226408" length="0.0848081"/>
      </geometry>
    </visual>
  </link>
</robot>
