<?xml version="1.0" ?>
<robot name="final">
  <joint name="final__link_2_JOINT_10" type="revolute">
    <parent link="final__link_2"/>
    <child link="final__link_1_clone_0"/>
    <origin xyz="-0.66268 -1.04989  0.1" rpy="1.5705 0     0"/>
    <axis xyz="0 0 1"/>
    <limit lower="-1.79769e+308" upper="1.79769e+308" effort="-1.0" velocity="-1.0"/>
  </joint>
  <joint name="final__link_2_JOINT_1" type="revolute">
    <parent link="final__link_2"/>
    <child link="final__link_1"/>
    <origin xyz="0.99552 -0.82764 -0.1" rpy="1.5705 0     0"/>
    <axis xyz="0 0 1"/>
    <limit lower="-1.79769e+308" upper="1.79769e+308" effort="-1.0" velocity="-1.0"/>
  </joint>
  <joint name="final__link_2_JOINT_8" type="revolute">
    <parent link="final__link_2"/>
    <child link="final__link_1_clone"/>
    <origin xyz="0.7543   0.93753 -0.1" rpy="1.5705 0     0"/>
    <axis xyz="0 0 1"/>
    <limit lower="-1.79769e+308" upper="1.79769e+308" effort="-1.0" velocity="-1.0"/>
  </joint>
  <joint name="final__link_2_JOINT_9" type="revolute">
    <parent link="final__link_2"/>
    <child link="final__link_1_clone_1"/>
    <origin xyz="-0.63337  0.8527   0.1" rpy="1.5705 0     0"/>
    <axis xyz="0 0 1"/>
    <limit lower="-1.79769e+308" upper="1.79769e+308" effort="-1.0" velocity="-1.0"/>
  </joint>
  <link name="final__link_1">
    <inertial>
      <mass value="1"/>
      <origin xyz="0 0 0" rpy="0 0 0"/>
      <inertia ixx="0.145833" ixy="0" ixz="0" iyy="0.145833" iyz="0" izz="0.125"/>
    </inertial>
    <collision name="final__collision">
      <origin xyz="0 0 0" rpy="0 0 0"/>
      <geometry>
        <cylinder radius="0.3" length="0.25"/>
      </geometry>
    </collision>
    <visual name="final__visual">
      <origin xyz="0 0 0" rpy="0 0 0"/>
      <geometry>
        <cylinder radius="0.3" length="0.2"/>
      </geometry>
    </visual>
  </link>
  <link name="final__link_1_clone">
    <inertial>
      <mass value="1"/>
      <origin xyz="0 0 0" rpy="0 0 0"/>
      <inertia ixx="0.145833" ixy="0" ixz="0" iyy="0.145833" iyz="0" izz="0.125"/>
    </inertial>
    <collision name="final__collision">
      <origin xyz="0 0 0" rpy="0 0 0"/>
      <geometry>
        <cylinder radius="0.3" length="0.25"/>
      </geometry>
    </collision>
    <visual name="final__visual">
      <origin xyz="0 0 0" rpy="0 0 0"/>
      <geometry>
        <cylinder radius="0.3" length="0.2"/>
      </geometry>
    </visual>
  </link>
  <link name="final__link_1_clone_0">
    <inertial>
      <mass value="1"/>
      <origin xyz="0 0 0" rpy="0 0 0"/>
      <inertia ixx="0.145833" ixy="0" ixz="0" iyy="0.145833" iyz="0" izz="0.125"/>
    </inertial>
    <collision name="final__collision">
      <origin xyz="0 0 0" rpy="0 0 0"/>
      <geometry>
        <cylinder radius="0.3" length="0.25"/>
      </geometry>
    </collision>
    <visual name="final__visual">
      <origin xyz="0 0 0" rpy="0 0 0"/>
      <geometry>
        <cylinder radius="0.3" length="0.2"/>
      </geometry>
    </visual>
  </link>
  <link name="final__link_1_clone_1">
    <inertial>
      <mass value="1"/>
      <origin xyz="0 0 0" rpy="0 0 0"/>
      <inertia ixx="0.145833" ixy="0" ixz="0" iyy="0.145833" iyz="0" izz="0.125"/>
    </inertial>
    <collision name="final__collision">
      <origin xyz="0 0 0" rpy="0 0 0"/>
      <geometry>
        <cylinder radius="0.3" length="0.25"/>
      </geometry>
    </collision>
    <visual name="final__visual">
      <origin xyz="0 0 0" rpy="0 0 0"/>
      <geometry>
        <cylinder radius="0.3" length="0.2"/>
      </geometry>
    </visual>
  </link>
  <link name="final__link_2">
    <inertial>
      <mass value="0.954167"/>
      <origin xyz="0 0 0" rpy="0 0 0"/>
      <inertia ixx="0.0984764" ixy="0" ixz="0" iyy="0.322504" iyz="0" izz="0.383055"/>
    </inertial>
    <collision name="final__collision">
      <origin xyz="-0.45378  0.0873   0" rpy="0 0 0"/>
      <geometry>
        <box size="1.95383 1 0.488344"/>
      </geometry>
    </collision>
    <visual name="final__visual">
      <origin xyz="-0.45378  0.0873   0" rpy="0 0 0"/>
      <geometry>
        <box size="1.95383 1 0.488344"/>
      </geometry>
    </visual>
  </link>
</robot>
